Workbook

Sheet Read Me First
A1: PartnerPortal — Functional Test Plan
A2: A click-by-click test plan for a non-technical tester. Work through the 'Test Cases' tab top to bottom. For each case follow the Steps, compare to Expected Result, then set Result to Pass/Fail and add Notes.
A4: Where you're testing
A5: Site address (URL): https://partnerportal.gmaadmin001.workers.dev
A6: Use Chrome or Edge. For 'logged out' tests, use a private/incognito window so old logins don't interfere.
A8: Stripe is in TEST mode — no real money moves
A9: Card that SUCCEEDS: 4242 4242 4242 4242
A10: Card that is DECLINED: 4000 0000 0000 0002
A11: Expiry: any future date (e.g. 12 / 34) CVC: any 3 digits (e.g. 123) ZIP: any 5 digits (e.g. 10001)
A13: Emails
A14: Use a REAL inbox you control — several tests need you to open an email and click a link.
A15: Use a FRESH email for every new registration. The Gmail '+' trick works: yourname+test1@gmail.com, +test2, etc.
... A28: On the Test Cases tab, the UAT column marks the core business journeys for sign-off (the happy-path registration/payment, login/reset, profile edit, claim, plan upgrade/badge, and admin approvals). Rows without a UAT mark are QA/system checks (validation, edge cases, role/tooling-dependent).

Sheet Test Cases
A1: ID | B1: UAT | C1: Section | D1: Test Case | E1: Preconditions | F1: Steps | G1: Expected Result | H1: Result | I1: Notes
A2: A1 | B2: Yes | C2: A — Public Directory & Search | D2: Browse the services directory | E2: Not logged in (incognito ok). | F2: 1. Go to /services. 2. Wait for the page to load. | G2: Search bar at top; a list of provider cards below (company name, category, short description, View Profile button). A count like 'N providers found' shows. | H2: Not Run
A3: A2 | C3: A — Public Directory & Search | D3: Filter by Category and Sub-Category | E3: On /services. | F3: 1. In Filters, open Service Category and pick one (e.g. Housing & Accommodation). 2. Click Apply Filters. 3. Type into Sub-Category (e.g. Corporate Housing) and click Apply Filters again. | G3: Results shrink to the category and a filter chip appears. Sub-Category narrows further. Count updates each time. | H3: Not Run
A4: A3 | C4: A — Public Directory & Search | D4: Filter by location (Country Served) | E4: On /services. | F4: 1. Click Clear all. 2. Open Country Served and choose a country with providers. 3. Click Apply Filters. | G4: Only providers serving that country remain; a 'Country: …' chip appears; count updates. Empty result shows 'No results found' + Clear Filters. | H4: Not Run
A5: A4 | C5: A — Public Directory & Search | D5: Filter by size / delivery / diversity, then Clear all | E5: On /services. | F5: 1. Click Clear all. 2. Pick a Company Size (e.g. 51–500), Apply Filters. 3. Click a Diversity toggle (e.g. Woman-Owned), Apply Filters. 4. Click Clear all. | G5: Each filter narrows results and adds a chip. Clear all removes every chip and restores the full list. | H5: Not Run
A6: A5 | B6: Yes | C6: A — Public Directory & Search | D6: Open a provider profile | E6: On /services. | F6: 1. Click View Profile on any card. | G6: Full profile opens: company name, description, meta chips (category, HQ, type), plan-dependent sections, and a '← Back to results' link. | H6: Not Run
A7: A6 | C7: A — Public Directory & Search | D7: Verified / Recommended badges show on the right providers | E7: Browsing /services. | F7: 1. Scan cards and several profiles. 2. Look for green '✓ Verified' on cards and VERIFIED / RECOMMENDED on profiles. | G7: Badges appear only on providers that have them, not on every provider. (Toggling is confirmed in G6/G7.) | H7: Not Run
A8: A7 | B8: Yes | C8: A — Public Directory & Search | D8: Free (Basic) listings hide paid-only content | E8: Browsing /services. | F8: 1. Open a Basic provider profile and a Professional/Premier one (plan shows in Company Info). | G8: Basic profile omits richer sections (About bio, Contact Details, Photo Gallery, Core Services); paid profile shows more. Nothing looks broken. | H8: Not Run
A9: B1 | B9: Yes | C9: B — Registration & Payment | D9: Register on the Basic (free) tier | E9: Fresh email. Not logged in. | F9: 1. /register. Step 1: click Vendor, choose Primary Category, Continue →. 2. Step 2: fill Company Name, Name, Email; Continue →. 3. Step 3: on Basic click Get Listed Free, Continue →. 4. Step 4: confirm Email, set Password + Confirm Password (all 5 rules on), click Create Account. | G9: No payment page. Success screen reads 'You're listed!' with 'Go to Dashboard →'. Clicking it lands on the dashboard, logged in. | H9: Not Run
A10: B2 | B10: Yes | C10: B — Registration & Payment | D10: Register Professional (monthly), pay with test card | E10: Fresh email. | F10: 1. /register, do Step 1 & 2. 2. Step 3: keep Monthly; Professional reads $25/mo; click Select Professional, then Pay & Register →. 3. On Stripe enter 4242 4242 4242 4242, future expiry, any CVC/ZIP, pay. | G10: Stripe accepts payment and returns to the site. You're told to check email to set your password. Stripe amount reads $25.00. | H10: Not Run
A11: B3 | C11: B — Registration & Payment | D11: Register Professional (annual) | E11: Fresh email. | F11: 1. Repeat B2 but on Step 3 flip toggle to Annual first. 2. Professional reads $250/yr (Save $50). Proceed and pay with 4242… | G11: Stripe charges $250.00 (annual price), not $25. | H11: Not Run
A12: B4 | B12: Yes | C12: B — Registration & Payment | D12: Register Premier (monthly and annual) | E12: Fresh email each run. | F12: 1. Register, choose Premier. 2. Monthly reads $50/mo; Annual reads $500/yr. 3. Pay with the success card. | G12: Stripe charges $50.00 (monthly) or $500.00 (annual) matching the choice. | H12: Not Run
A13: B5 | B13: Yes | C13: B — Registration & Payment | D13: Set password from invite email, then sign in | E13: Completed B2; access that inbox. | F13: 1. Open the inbox used in B2. 2. Open the branded email, click its button. 3. On 'Set your password', set New + Confirm Password, click Set Password. 4. Click 'Go to Sign In →' and sign in. | G13: Link opens the password page (not an error). After setting it you can sign in and reach the dashboard. Plan shows Professional. | H13: Not Run
A14: B6 | C14: B — Registration & Payment | D14: Validation blocks incomplete steps | E14: On /register. | F14: 1. Step 1: click Continue → without a Primary Category. 2. Step 2: clear Company Name (or Name/Email), Continue →. 3. Step 4 (Basic): type two different passwords. | G14: Each time the form stops you — field flagged and/or button disabled. Mismatched passwords show a clear message and won't submit. | H14: Not Run
A15: B7 | C15: B — Registration & Payment | D15: Category / coverage limits match the tier | E15: Have Basic (B1); optionally Pro & Premier. | F15: 1. As Basic, in the profile/listing editor try to add a 2nd category or service area. 2. Compare allowances across Pro and Premier if available. | G15: Basic = 1, Professional = 3, Premier = unlimited; exceeding is blocked or prompts upgrade. If not visibly enforced, record it (known to-confirm). | H15: Not Run
A16: C1 | B16: Yes | C16: C — Authentication | D16: Log in with valid credentials | E16: Have the Basic account (B1). Incognito. | F16: 1. /login, enter Email, Continue →. 2. Enter Password, click Sign In. | G16: You land on /dashboard, logged in as that provider. | H16: Not Run
A17: C2 | C17: C — Authentication | D17: Log in with the wrong password | E17: Have an account. | F17: 1. Repeat C1 but type an incorrect password at Sign In. | G17: A clear error appears; you are NOT logged in / not taken to the dashboard. | H17: Not Run
A18: C3 | B18: Yes | C18: C — Authentication | D18: Reset a forgotten password | E18: Have an account + inbox access. | F18: 1. /login, enter email, Continue →, click Forgot password?. 2. Open the 'Reset your password' email, click its button. 3. Set a new password, then sign in with it. | G18: Reset email arrives (check Spam). Link opens the reset page; new password works; OLD password no longer works. | H18: Not Run
A19: C4 | B19: Yes | C19: C — Authentication | D19: Admin magic-link login (email only) | E19: Have admin email + admin inbox. | F19: 1. Incognito → /login. 2. Enter the admin email, click Continue →. | G19: Switches to 'Check your email' (no password asked). Click the link in the admin inbox → you land in /admin, not /dashboard. | H19: Not Run
A20: C5 | C20: C — Authentication | D20: Normal email goes to password login | E20: Have a regular provider email. | F20: 1. /login, enter a regular provider email, Continue →. | G20: It asks for a Password (normal login), NOT a magic link. | H20: Not Run
A21: C6 | C21: C — Authentication | D21: Protected pages require login | E21: Fresh incognito, not logged in. | F21: 1. Go directly to /dashboard. | G21: You are redirected to the login/register screen instead of seeing a dashboard. | H21: Not Run
A22: D1 | C22: D — Dashboard & Profile | D22: Dashboard overview loads | E22: Logged in (use Professional from B5). | F22: 1. View the main dashboard. | G22: Welcome banner stat cards (Plan Tier, Status, Listing Type, Verified Badge/Member Since), a Profile Completion meter with %, and Quick Actions. | H22: Not Run
A23: D2 | B23: Yes | C23: D — Dashboard & Profile | D23: Edit profile and confirm it shows publicly | E23: Logged in. | F23: 1. Open Edit Company Profile (or Profile in sidebar). 2. Change a visible field (e.g. Short Description), save. 3. Open View Public Listing and find the change. | G23: Save succeeds; the new text appears on your public profile page. | H23: Not Run
A24: D3 | B24: Yes | C24: D — Dashboard & Profile | D24: Upload a company logo | E24: Logged in. | F24: 1. In the profile editor use the logo upload to pick an image from your computer. | G24: Thumbnail preview appears; you can remove/replace; after saving the logo shows on your public listing/card. | H24: Not Run
A25: D4 | C25: D — Dashboard & Profile | D25: Upload photo gallery (Premier only) | E25: Logged in as Premier (B4). | F25: 1. In the profile editor add photos to the gallery. 2. Open your public profile. | G25: Photos upload and appear in the Photo Gallery. On Basic/Professional the control is locked (see D5). | H25: Not Run
A26: D5 | C26: D — Dashboard & Profile | D26: Locked fields show the upgrade path | E26: Logged in as Basic. | F26: 1. Open the profile editor. | G26: Paid-only fields (bio, logo, gallery) are greyed/disabled with a ★ upgrade marker and hover tooltip. Nothing is hidden. | H26: Not Run
A27: D6 | C27: D — Dashboard & Profile | D27: 'View Public Listing' opens the correct page | E27: Logged in. | F27: 1. From the dashboard click View Public Listing. | G27: Opens YOUR public profile (URL matches your company). Still correct after a plan change that rotates the URL (see E2). | H27: Not Run
A28: E1 | B28: Yes | C28: E — Plans & Badge | D28: Upgrade the plan | E28: Logged in as Basic. Open /dashboard/plans. | F28: 1. Click Upgrade to Professional (or Premier). 2. Complete Stripe checkout with 4242… if prompted. | G28: After payment the Current Plan banner updates to the new tier; previously-locked features become editable. | H28: Not Run
A29: E2 | C29: E — Plans & Badge | D29: Downgrade the plan | E29: Logged in as Professional/Premier. | F29: 1. Click Downgrade to … on a lower plan. 2. Read the Confirm Downgrade modal (lists features lost), click Confirm Downgrade. | G29: Warning modal appears first. After confirm, plan changes, paid features re-lock; to-Basic says it won't renew but stays active until period end. Slug may change — verify View Public Listing (D6). | H29: Not Run
A30: E3 | C30: E — Plans & Badge | D30: Switch billing monthly ↔ annual | E30: Logged in as a paid member. | F30: 1. Use the Monthly/Annual toggle and click Switch to Annual (or Switch to Monthly) on your current plan. 2. Complete any Stripe step. | G30: Billing cycle on the Current Plan banner updates; Stripe prorates; no duplicate subscription is created. | H30: Not Run
A31: E4 | B31: Yes | C31: E — Plans & Badge | D31: Buy the Verified Badge (Professional+) | E31: Logged in as Professional. | F31: 1. On the plans page click '✦ Get Verified Badge — $100 one-time →'. 2. Pay $100 with 4242… 3. Badge becomes Active only after admin verifies (run G6, then return). | G31: Checkout charges $100.00. After admin verification: '✦ Verified Badge Active / OWNED' chip on plans page and a 'GMA Verified' pill on the dashboard. | H31: Not Run
A32: E5 | C32: E — Plans & Badge | D32: Badge re-purchase is blocked | E32: After E4 + G6 (badge owned). | F32: 1. Revisit the plans page. | G32: The badge button is replaced by the '✦ Verified Badge Active / OWNED' chip — no way to buy it twice. | H32: Not Run
A33: E6a | C33: E — Plans & Badge | D33: Payment declined at checkout | E33: Logged in as a paid member. | F33: 1. Start an upgrade (E1) or badge purchase (E4) but on Stripe use the declined card 4000 0000 0000 0002. | G33: Stripe shows a card-declined error; the upgrade/badge does NOT apply; plan stays unchanged; you can retry with a good card. | H33: Not Run
A34: E6b | C34: E — Plans & Badge | D34: Recurring failure → Suspended (ASSISTED — needs Stripe dashboard) | E34: Paid test subscriber; someone with Stripe access. | F34: 1. Have Stripe access simulate a failed renewal invoice (or use a test clock) for that account. 2. Refresh that account's dashboard. | G34: Account Status changes to past_due then Suspended; the listing reflects the suspended state. | H34: Not Run
A35: F1 | B35: Yes | C35: F — Claim Flow | D35: Claim a listing (new account + Basic) | E35: An ownerless imported listing (ask Paul). | F35: 1. On the ownerless profile click the 'Is this your company?' / Claim link (→ /claim/<slug>). 2. Fill Your Name, Business Email (fresh), optional Role, Password. 3. Under Select Plan choose Basic, click 'Claim Listing — Free'. | G35: Success screen 'Claim Submitted!' ('under review … 1–2 business days'). The claim now needs admin approval (G5). | H35: Not Run
A36: F2 | C36: F — Claim Flow | D36: Start a claim while logged out routes back | E36: Incognito; an ownerless profile. | F36: 1. Open an ownerless profile, click the claim link. 2. If prompted to sign in/register, complete it. | G36: After authenticating you return to the claim/listing you started from — not a generic page. | H36: Not Run
A37: F3 | C37: F — Claim Flow | D37: Claim-then-pay (must subscribe before editing) | E37: On /claim/<slug>. | F37: 1. Choose Professional (or Premier); button reads 'Subscribe & Claim — $25/mo' (or chosen price). 2. Complete Stripe checkout with the success card. | G37: Payment taken; claim submitted for review; listing can't be edited as paid until the claim is approved (G5). Button price matches plan/billing. | H37: Not Run
A38: G1 | C38: G — Admin Dashboard | D38: Admin dashboard loads with stats | E38: Signed in as admin (C4). | F38: 1. After magic-link login you're on /admin. | G38: Stat cards: Active Listings, New This Week, Pending Registrations, Pending Claims, Pending Badges, By Type. If anything pends, a banner 'N items need your attention…' with 'Review pending →'. | H38: Not Run
A39: G2 | C39: G — Admin Dashboard | D39: Search for a registration | E39: On /admin. | F39: 1. In 'Search by company name or email…' type a test account's name/email. 2. Try the All Types and All Plans dropdowns. | G39: Table filters to matches; 'X of Y' count updates. Dropdowns narrow the list. | H39: Not Run
A40: G3 | C40: G — Admin Dashboard | D40: Editing requires Edit, and saves persist | E40: On /admin. | F40: 1. Click Edit on a test record's row. 2. Change a field (e.g. HQ City) and click Save Changes. 3. Verify on the table and the public profile. | G40: Fields are read-only until you click Edit. Save Changes persists (reload to confirm). Cancel discards edits. | H40: Not Run
...

Sheet Summary
A1: Test Run Summary
A3: Tester:
A4: Date:
A5: Build / URL tested: | B5: https://partnerportal.gmaadmin001.workers.dev
A7: Section | B7: Total | C7: Pass | D7: Fail | E7: Blocked | F7: Not Run
A8: A — Public Directory & Search | B8: =COUNTIF('Test Cases'!$B$2:$B$48,"A —*") | C8: =COUNTIFS('Test Cases'!$B$2:$B$48,"A —*",'Test Cases'!$G$2:$G$48,"Pass") | D8: =COUNTIFS('Test Cases'!$B$2:$B$48,"A —*",'Test Cases'!$G$2:$G$48,"Fail") | E8: =COUNTIFS('Test Cases'!$B$2:$B$48,"A —*",'Test Cases'!$G$2:$G$48,"Blocked") | F8: =COUNTIFS('Test Cases'!$B$2:$B$48,"A —*",'Test Cases'!$G$2:$G$48,"Not Run")
A9: B — Registration & Payment | B9: =COUNTIF('Test Cases'!$B$2:$B$48,"B —*") | C9: =COUNTIFS('Test Cases'!$B$2:$B$48,"B —*",'Test Cases'!$G$2:$G$48,"Pass") | D9: =COUNTIFS('Test Cases'!$B$2:$B$48,"B —*",'Test Cases'!$G$2:$G$48,"Fail") | E9: =COUNTIFS('Test Cases'!$B$2:$B$48,"B —*",'Test Cases'!$G$2:$G$48,"Blocked") | F9: =COUNTIFS('Test Cases'!$B$2:$B$48,"B —*",'Test Cases'!$G$2:$G$48,"Not Run")
A10: C — Authentication | B10: =COUNTIF('Test Cases'!$B$2:$B$48,"C —*") | C10: =COUNTIFS('Test Cases'!$B$2:$B$48,"C —*",'Test Cases'!$G$2:$G$48,"Pass") | D10: =COUNTIFS('Test Cases'!$B$2:$B$48,"C —*",'Test Cases'!$G$2:$G$48,"Fail") | E10: =COUNTIFS('Test Cases'!$B$2:$B$48,"C —*",'Test Cases'!$G$2:$G$48,"Blocked") | F10: =COUNTIFS('Test Cases'!$B$2:$B$48,"C —*",'Test Cases'!$G$2:$G$48,"Not Run")
A11: D — Dashboard & Profile | B11: =COUNTIF('Test Cases'!$B$2:$B$48,"D —*") | C11: =COUNTIFS('Test Cases'!$B$2:$B$48,"D —*",'Test Cases'!$G$2:$G$48,"Pass") | D11: =COUNTIFS('Test Cases'!$B$2:$B$48,"D —*",'Test Cases'!$G$2:$G$48,"Fail") | E11: =COUNTIFS('Test Cases'!$B$2:$B$48,"D —*",'Test Cases'!$G$2:$G$48,"Blocked") | F11: =COUNTIFS('Test Cases'!$B$2:$B$48,"D —*",'Test Cases'!$G$2:$G$48,"Not Run")
A12: E — Plans & Badge | B12: =COUNTIF('Test Cases'!$B$2:$B$48,"E —*") | C12: =COUNTIFS('Test Cases'!$B$2:$B$48,"E —*",'Test Cases'!$G$2:$G$48,"Pass") | D12: =COUNTIFS('Test Cases'!$B$2:$B$48,"E —*",'Test Cases'!$G$2:$G$48,"Fail") | E12: =COUNTIFS('Test Cases'!$B$2:$B$48,"E —*",'Test Cases'!$G$2:$G$48,"Blocked") | F12: =COUNTIFS('Test Cases'!$B$2:$B$48,"E —*",'Test Cases'!$G$2:$G$48,"Not Run")
A13: F — Claim Flow | B13: =COUNTIF('Test Cases'!$B$2:$B$48,"F —*") | C13: =COUNTIFS('Test Cases'!$B$2:$B$48,"F —*",'Test Cases'!$G$2:$G$48,"Pass") | D13: =COUNTIFS('Test Cases'!$B$2:$B$48,"F —*",'Test Cases'!$G$2:$G$48,"Fail") | E13: =COUNTIFS('Test Cases'!$B$2:$B$48,"F —*",'Test Cases'!$G$2:$G$48,"Blocked") | F13: =COUNTIFS('Test Cases'!$B$2:$B$48,"F —*",'Test Cases'!$G$2:$G$48,"Not Run")
A14: G — Admin Dashboard | B14: =COUNTIF('Test Cases'!$B$2:$B$48,"G —*") | C14: =COUNTIFS('Test Cases'!$B$2:$B$48,"G —*",'Test Cases'!$G$2:$G$48,"Pass") | D14: =COUNTIFS('Test Cases'!$B$2:$B$48,"G —*",'Test Cases'!$G$2:$G$48,"Fail") | E14: =COUNTIFS('Test Cases'!$B$2:$B$48,"G —*",'Test Cases'!$G$2:$G$48,"Blocked") | F14: =COUNTIFS('Test Cases'!$B$2:$B$48,"G —*",'Test Cases'!$G$2:$G$48,"Not Run")
A15: H — Email Notifications | B15: =COUNTIF('Test Cases'!$B$2:$B$48,"H —*") | C15: =COUNTIFS('Test Cases'!$B$2:$B$48,"H —*",'Test Cases'!$G$2:$G$48,"Pass") | D15: =COUNTIFS('Test Cases'!$B$2:$B$48,"H —*",'Test Cases'!$G$2:$G$48,"Fail") | E15: =COUNTIFS('Test Cases'!$B$2:$B$48,"H —*",'Test Cases'!$G$2:$G$48,"Blocked") | F15: =COUNTIFS('Test Cases'!$B$2:$B$48,"H —*",'Test Cases'!$G$2:$G$48,"Not Run")
A16: TOTAL | B16: =SUM(B8:B15) | C16: =SUM(C8:C15) | D16: =SUM(D8:D15) | E16: =SUM(E8:E15) | F16: =SUM(F8:F15)
